Exception on /dump [GET]
Traceback (most recent call last):
  File "c:\users\nano\appdata\local\programs\python\python37-32\lib\site-packages\flask\app.py", line 2292, in wsgi_app
    response = self.full_dispatch_request()
  File "c:\users\nano\appdata\local\programs\python\python37-32\lib\site-packages\flask\app.py", line 1815, in full_dispatch_request
    rv = self.handle_user_exception(e)
  File "c:\users\nano\appdata\local\programs\python\python37-32\lib\site-packages\flask\app.py", line 1718, in handle_user_exception
    reraise(exc_type, exc_value, tb)
  File "c:\users\nano\appdata\local\programs\python\python37-32\lib\site-packages\flask\_compat.py", line 35, in reraise
    raise value
  File "c:\users\nano\appdata\local\programs\python\python37-32\lib\site-packages\flask\app.py", line 1813, in full_dispatch_request
    rv = self.dispatch_request()
  File "c:\users\nano\appdata\local\programs\python\python37-32\lib\site-packages\flask\app.py", line 1799, in dispatch_request
    return self.view_functions[rule.endpoint](**req.view_args)
  File "C:\Workspace\TIMS\Backend_Processor\DownloadAgent\app.py", line 66, in dumpDatabase
    exportThreatStatInstance = ExportThreatStats()
  File "C:\Workspace\TIMS\Backend_Processor\DownloadAgent\ExportAgent\ExportThreatStats.py", line 56, in __init__
    sqliteDataStoreInstance = DataStore_Modules.DataStore_SQLite.SQLiteDataStore()
AttributeError: module 'DataStore_Modules' has no attribute 'DataStore_SQLite'
Exception on /dump [GET]
Traceback (most recent call last):
  File "c:\python\python37-32\lib\site-packages\flask\app.py", line 2292, in wsgi_app
    response = self.full_dispatch_request()
  File "c:\python\python37-32\lib\site-packages\flask\app.py", line 1815, in full_dispatch_request
    rv = self.handle_user_exception(e)
  File "c:\python\python37-32\lib\site-packages\flask\app.py", line 1718, in handle_user_exception
    reraise(exc_type, exc_value, tb)
  File "c:\python\python37-32\lib\site-packages\flask\_compat.py", line 35, in reraise
    raise value
  File "c:\python\python37-32\lib\site-packages\flask\app.py", line 1813, in full_dispatch_request
    rv = self.dispatch_request()
  File "c:\python\python37-32\lib\site-packages\flask\app.py", line 1799, in dispatch_request
    return self.view_functions[rule.endpoint](**req.view_args)
  File "C:\Workspace\TIMS\Backend_Processor\DownloadAgent\app.py", line 67, in dumpDatabase
    return exportThreatStatInstance.exportThreatStats()
  File "C:\Workspace\TIMS\Backend_Processor\DownloadAgent\ExportAgent\ExportThreatStats.py", line 60, in exportThreatStats
    cursor.execute(sqlString)
sqlite3.OperationalError: no such table: ThreatStatsDB
Exception on /download/adsasdas.json [GET]
Traceback (most recent call last):
  File "C:\Workspace\TIMS\Backend_Processor\DownloadAgent\app.py", line 75, in downloadFile
    return send_file('./ExportedFiles/' + path, as_attachment=True)
  File "c:\python\python37-32\lib\site-packages\flask\helpers.py", line 588, in send_file
    file = open(filename, 'rb')
FileNotFoundError: [Errno 2] No such file or directory: 'C:\\Workspace\\TIMS\\Backend_Processor\\DownloadAgent\\./ExportedFiles/adsasdas.json'

During handling of the above exception, another exception occurred:

Traceback (most recent call last):
  File "c:\python\python37-32\lib\site-packages\flask\app.py", line 2292, in wsgi_app
    response = self.full_dispatch_request()
  File "c:\python\python37-32\lib\site-packages\flask\app.py", line 1815, in full_dispatch_request
    rv = self.handle_user_exception(e)
  File "c:\python\python37-32\lib\site-packages\flask\app.py", line 1718, in handle_user_exception
    reraise(exc_type, exc_value, tb)
  File "c:\python\python37-32\lib\site-packages\flask\_compat.py", line 35, in reraise
    raise value
  File "c:\python\python37-32\lib\site-packages\flask\app.py", line 1813, in full_dispatch_request
    rv = self.dispatch_request()
  File "c:\python\python37-32\lib\site-packages\flask\app.py", line 1799, in dispatch_request
    return self.view_functions[rule.endpoint](**req.view_args)
  File "C:\Workspace\TIMS\Backend_Processor\DownloadAgent\app.py", line 77, in downloadFile
    self.log.exception(e)
NameError: name 'self' is not defined
